{"uuid": "d756e23b-8c1b-4fbb-9d50-73c2986be97f", "children": ["6f3a50f7-48de-401e-a740-0c56ddb3a4b9", "48daeba0-2a3a-4aa6-9b51-8d17bdf8cc9c", "452a6aff-20f8-4afd-b2a6-68433885b2cb", "1db6206a-f623-4718-b9ac-98dafbb60dfe", "67e029d5-3417-4fea-a8f5-89747b4dd47b", "06e8a7a0-14a0-4ced-a367-824fb95619ba", "939e8e4b-668a-4b02-b38d-eb672b4e55a2", "c5415d85-b634-4ae4-ac97-a7003af37afe", "d3257f5a-830f-427f-a49b-7aa4008a4f84", "264469b6-edc8-4f2b-95c6-b1000fa2987a", "68567f42-bd96-4422-a06f-bcb66d478c2a", "226fc991-8f48-4faf-9c14-26e6cf4ace7a", "992f192d-6240-41ea-9bbc-b41b96e6727e", "98a82f8e-52ae-4336-a7ee-7ac09ea9a22b", "921f1f53-0aa4-4a17-84e6-6f0b72a79968", "0a8892c6-1e5e-4a62-82cc-0ff6ddf417b4", "ebae43ef-8eb3-4961-ac36-960c886fced9", "ff0d6ee3-8c18-449e-826a-214cdec2c66e"], "befores": [{"name": "access_web", "status": "broken", "statusDetails": {"message": "selenium.common.exceptions.WebDriverException: Message: 'chromedriver' executable needs to be in PATH. Please see https://chromedriver.chromium.org/home\n\n", "trace": "  File \"d:\\develop\\python\\python38\\lib\\site-packages\\pluggy\\_callers.py\", line 39, in _multicall\n    res = hook_impl.function(*args)\n  File \"d:\\develop\\python\\python38\\lib\\site-packages\\_pytest\\fixtures.py\", line 1122, in pytest_fixture_setup\n    result = call_fixture_func(fixturefunc, request, kwargs)\n  File \"d:\\develop\\python\\python38\\lib\\site-packages\\_pytest\\fixtures.py\", line 917, in call_fixture_func\n    fixture_result = next(generator)\n  File \"D:\\Develop\\JetBrains\\PyCharm\\PycharmProjects\\Web_Framework_V3\\TestCases\\Test0LoginCases\\conftest.py\", line 27, in access_web\n    driver = webdriver.Chrome()\n  File \"d:\\develop\\python\\python38\\lib\\site-packages\\selenium\\webdriver\\chrome\\webdriver.py\", line 70, in __init__\n    super(WebDriver, self).__init__(DesiredCapabilities.CHROME['browserName'], \"goog\",\n  File \"d:\\develop\\python\\python38\\lib\\site-packages\\selenium\\webdriver\\chromium\\webdriver.py\", line 90, in __init__\n    self.service.start()\n  File \"d:\\develop\\python\\python38\\lib\\site-packages\\selenium\\webdriver\\common\\service.py\", line 81, in start\n    raise WebDriverException(\n"}, "start": 1647233576580, "stop": 1647233576596}, {"name": "access_web", "status": "broken", "statusDetails": {"message": "selenium.common.exceptions.WebDriverException: Message: 'chromedriver' executable needs to be in PATH. Please see https://chromedriver.chromium.org/home\n\n", "trace": "  File \"d:\\develop\\python\\python38\\lib\\site-packages\\pluggy\\_callers.py\", line 39, in _multicall\n    res = hook_impl.function(*args)\n  File \"d:\\develop\\python\\python38\\lib\\site-packages\\_pytest\\fixtures.py\", line 1122, in pytest_fixture_setup\n    result = call_fixture_func(fixturefunc, request, kwargs)\n  File \"d:\\develop\\python\\python38\\lib\\site-packages\\_pytest\\fixtures.py\", line 917, in call_fixture_func\n    fixture_result = next(generator)\n  File \"D:\\Develop\\JetBrains\\PyCharm\\PycharmProjects\\Web_Framework_V3\\TestCases\\Test0LoginCases\\conftest.py\", line 27, in access_web\n    driver = webdriver.Chrome()\n  File \"d:\\develop\\python\\python38\\lib\\site-packages\\selenium\\webdriver\\chrome\\webdriver.py\", line 70, in __init__\n    super(WebDriver, self).__init__(DesiredCapabilities.CHROME['browserName'], \"goog\",\n  File \"d:\\develop\\python\\python38\\lib\\site-packages\\selenium\\webdriver\\chromium\\webdriver.py\", line 90, in __init__\n    self.service.start()\n  File \"d:\\develop\\python\\python38\\lib\\site-packages\\selenium\\webdriver\\common\\service.py\", line 81, in start\n    raise WebDriverException(\n"}, "start": 1647233581768, "stop": 1647233581768}, {"name": "access_web", "status": "broken", "statusDetails": {"message": "selenium.common.exceptions.WebDriverException: Message: 'chromedriver' executable needs to be in PATH. Please see https://chromedriver.chromium.org/home\n\n", "trace": "  File \"d:\\develop\\python\\python38\\lib\\site-packages\\pluggy\\_callers.py\", line 39, in _multicall\n    res = hook_impl.function(*args)\n  File \"d:\\develop\\python\\python38\\lib\\site-packages\\_pytest\\fixtures.py\", line 1122, in pytest_fixture_setup\n    result = call_fixture_func(fixturefunc, request, kwargs)\n  File \"d:\\develop\\python\\python38\\lib\\site-packages\\_pytest\\fixtures.py\", line 917, in call_fixture_func\n    fixture_result = next(generator)\n  File \"D:\\Develop\\JetBrains\\PyCharm\\PycharmProjects\\Web_Framework_V3\\TestCases\\Test0LoginCases\\conftest.py\", line 27, in access_web\n    driver = webdriver.Chrome()\n  File \"d:\\develop\\python\\python38\\lib\\site-packages\\selenium\\webdriver\\chrome\\webdriver.py\", line 70, in __init__\n    super(WebDriver, self).__init__(DesiredCapabilities.CHROME['browserName'], \"goog\",\n  File \"d:\\develop\\python\\python38\\lib\\site-packages\\selenium\\webdriver\\chromium\\webdriver.py\", line 90, in __init__\n    self.service.start()\n  File \"d:\\develop\\python\\python38\\lib\\site-packages\\selenium\\webdriver\\common\\service.py\", line 81, in start\n    raise WebDriverException(\n"}, "start": 1647233586812, "stop": 1647233586814}, {"name": "access_web", "status": "broken", "statusDetails": {"message": "selenium.common.exceptions.WebDriverException: Message: 'chromedriver' executable needs to be in PATH. Please see https://chromedriver.chromium.org/home\n\n", "trace": "  File \"d:\\develop\\python\\python38\\lib\\site-packages\\pluggy\\_callers.py\", line 39, in _multicall\n    res = hook_impl.function(*args)\n  File \"d:\\develop\\python\\python38\\lib\\site-packages\\_pytest\\fixtures.py\", line 1122, in pytest_fixture_setup\n    result = call_fixture_func(fixturefunc, request, kwargs)\n  File \"d:\\develop\\python\\python38\\lib\\site-packages\\_pytest\\fixtures.py\", line 917, in call_fixture_func\n    fixture_result = next(generator)\n  File \"D:\\Develop\\JetBrains\\PyCharm\\PycharmProjects\\Web_Framework_V3\\TestCases\\Test0LoginCases\\conftest.py\", line 27, in access_web\n    driver = webdriver.Chrome()\n  File \"d:\\develop\\python\\python38\\lib\\site-packages\\selenium\\webdriver\\chrome\\webdriver.py\", line 70, in __init__\n    super(WebDriver, self).__init__(DesiredCapabilities.CHROME['browserName'], \"goog\",\n  File \"d:\\develop\\python\\python38\\lib\\site-packages\\selenium\\webdriver\\chromium\\webdriver.py\", line 90, in __init__\n    self.service.start()\n  File \"d:\\develop\\python\\python38\\lib\\site-packages\\selenium\\webdriver\\common\\service.py\", line 81, in start\n    raise WebDriverException(\n"}, "start": 1647233591905, "stop": 1647233591905}, {"name": "access_web", "status": "broken", "statusDetails": {"message": "selenium.common.exceptions.WebDriverException: Message: 'chromedriver' executable needs to be in PATH. Please see https://chromedriver.chromium.org/home\n\n", "trace": "  File \"d:\\develop\\python\\python38\\lib\\site-packages\\pluggy\\_callers.py\", line 39, in _multicall\n    res = hook_impl.function(*args)\n  File \"d:\\develop\\python\\python38\\lib\\site-packages\\_pytest\\fixtures.py\", line 1122, in pytest_fixture_setup\n    result = call_fixture_func(fixturefunc, request, kwargs)\n  File \"d:\\develop\\python\\python38\\lib\\site-packages\\_pytest\\fixtures.py\", line 917, in call_fixture_func\n    fixture_result = next(generator)\n  File \"D:\\Develop\\JetBrains\\PyCharm\\PycharmProjects\\Web_Framework_V3\\TestCases\\Test0LoginCases\\conftest.py\", line 27, in access_web\n    driver = webdriver.Chrome()\n  File \"d:\\develop\\python\\python38\\lib\\site-packages\\selenium\\webdriver\\chrome\\webdriver.py\", line 70, in __init__\n    super(WebDriver, self).__init__(DesiredCapabilities.CHROME['browserName'], \"goog\",\n  File \"d:\\develop\\python\\python38\\lib\\site-packages\\selenium\\webdriver\\chromium\\webdriver.py\", line 90, in __init__\n    self.service.start()\n  File \"d:\\develop\\python\\python38\\lib\\site-packages\\selenium\\webdriver\\common\\service.py\", line 81, in start\n    raise WebDriverException(\n"}, "start": 1647233596945, "stop": 1647233596945}, {"name": "access_web", "status": "broken", "statusDetails": {"message": "selenium.common.exceptions.WebDriverException: Message: 'chromedriver' executable needs to be in PATH. Please see https://chromedriver.chromium.org/home\n\n", "trace": "  File \"d:\\develop\\python\\python38\\lib\\site-packages\\pluggy\\_callers.py\", line 39, in _multicall\n    res = hook_impl.function(*args)\n  File \"d:\\develop\\python\\python38\\lib\\site-packages\\_pytest\\fixtures.py\", line 1122, in pytest_fixture_setup\n    result = call_fixture_func(fixturefunc, request, kwargs)\n  File \"d:\\develop\\python\\python38\\lib\\site-packages\\_pytest\\fixtures.py\", line 917, in call_fixture_func\n    fixture_result = next(generator)\n  File \"D:\\Develop\\JetBrains\\PyCharm\\PycharmProjects\\Web_Framework_V3\\TestCases\\Test0LoginCases\\conftest.py\", line 27, in access_web\n    driver = webdriver.Chrome()\n  File \"d:\\develop\\python\\python38\\lib\\site-packages\\selenium\\webdriver\\chrome\\webdriver.py\", line 70, in __init__\n    super(WebDriver, self).__init__(DesiredCapabilities.CHROME['browserName'], \"goog\",\n  File \"d:\\develop\\python\\python38\\lib\\site-packages\\selenium\\webdriver\\chromium\\webdriver.py\", line 90, in __init__\n    self.service.start()\n  File \"d:\\develop\\python\\python38\\lib\\site-packages\\selenium\\webdriver\\common\\service.py\", line 81, in start\n    raise WebDriverException(\n"}, "start": 1647233602053, "stop": 1647233602053}, {"name": "access_web", "status": "broken", "statusDetails": {"message": "selenium.common.exceptions.WebDriverException: Message: 'chromedriver' executable needs to be in PATH. Please see https://chromedriver.chromium.org/home\n\n", "trace": "  File \"d:\\develop\\python\\python38\\lib\\site-packages\\pluggy\\_callers.py\", line 39, in _multicall\n    res = hook_impl.function(*args)\n  File \"d:\\develop\\python\\python38\\lib\\site-packages\\_pytest\\fixtures.py\", line 1122, in pytest_fixture_setup\n    result = call_fixture_func(fixturefunc, request, kwargs)\n  File \"d:\\develop\\python\\python38\\lib\\site-packages\\_pytest\\fixtures.py\", line 917, in call_fixture_func\n    fixture_result = next(generator)\n  File \"D:\\Develop\\JetBrains\\PyCharm\\PycharmProjects\\Web_Framework_V3\\TestCases\\Test0LoginCases\\conftest.py\", line 27, in access_web\n    driver = webdriver.Chrome()\n  File \"d:\\develop\\python\\python38\\lib\\site-packages\\selenium\\webdriver\\chrome\\webdriver.py\", line 70, in __init__\n    super(WebDriver, self).__init__(DesiredCapabilities.CHROME['browserName'], \"goog\",\n  File \"d:\\develop\\python\\python38\\lib\\site-packages\\selenium\\webdriver\\chromium\\webdriver.py\", line 90, in __init__\n    self.service.start()\n  File \"d:\\develop\\python\\python38\\lib\\site-packages\\selenium\\webdriver\\common\\service.py\", line 81, in start\n    raise WebDriverException(\n"}, "start": 1647233607093, "stop": 1647233607093}, {"name": "access_web", "status": "broken", "statusDetails": {"message": "selenium.common.exceptions.WebDriverException: Message: 'chromedriver' executable needs to be in PATH. Please see https://chromedriver.chromium.org/home\n\n", "trace": "  File \"d:\\develop\\python\\python38\\lib\\site-packages\\pluggy\\_callers.py\", line 39, in _multicall\n    res = hook_impl.function(*args)\n  File \"d:\\develop\\python\\python38\\lib\\site-packages\\_pytest\\fixtures.py\", line 1122, in pytest_fixture_setup\n    result = call_fixture_func(fixturefunc, request, kwargs)\n  File \"d:\\develop\\python\\python38\\lib\\site-packages\\_pytest\\fixtures.py\", line 917, in call_fixture_func\n    fixture_result = next(generator)\n  File \"D:\\Develop\\JetBrains\\PyCharm\\PycharmProjects\\Web_Framework_V3\\TestCases\\Test0LoginCases\\conftest.py\", line 27, in access_web\n    driver = webdriver.Chrome()\n  File \"d:\\develop\\python\\python38\\lib\\site-packages\\selenium\\webdriver\\chrome\\webdriver.py\", line 70, in __init__\n    super(WebDriver, self).__init__(DesiredCapabilities.CHROME['browserName'], \"goog\",\n  File \"d:\\develop\\python\\python38\\lib\\site-packages\\selenium\\webdriver\\chromium\\webdriver.py\", line 90, in __init__\n    self.service.start()\n  File \"d:\\develop\\python\\python38\\lib\\site-packages\\selenium\\webdriver\\common\\service.py\", line 81, in start\n    raise WebDriverException(\n"}, "start": 1647233612178, "stop": 1647233612178}, {"name": "access_web", "status": "passed", "start": 1647233617223, "stop": 1647233620403}], "afters": [{"name": "access_web::0", "status": "passed", "start": 1647233627750, "stop": 1647233630312}], "start": 1647233617223, "stop": 1647233630312}